<?xml version="1.0" encoding="utf-8"?>
<!-- This URDF was automatically created by SolidWorks to URDF Exporter! Originally created by Stephen Brawner (brawner@gmail.com) 
     Commit Version: 1.6.0-4-g7f85cfe  Build Version: 1.6.7995.38578
     For more information, please see http://wiki.ros.org/sw_urdf_exporter -->
<robot
  name="robot_description">

<link name="base_footprint"/>
 
    <joint name="base_footprint_joint" type="fixed">
      <origin xyz="0 0 0.065" rpy="0 0 0" />
      <parent link="base_footprint"/>
      <child link="base_link" />
    </joint>

  <link
    name="base_link">
    <inertial>
      <origin
        xyz="0.000157829100166623 -0.00314105508408472 0.0214281198373021"
        rpy="0 0 0" />
      <mass
        value="0.735451341319549" />
      <inertia
        ixx="0.0040759669785994"
        ixy="-3.36441512090779E-07"
        ixz="-6.7607661151319E-08"
        iyy="0.00172437353361341"
        iyz="4.00243120794907E-06"
        izz="0.00578039602875465" />
    </inertial>
    <visual>
      <origin
        xyz="0 0 0"
        rpy="0 0 0" />
      <geometry>
        <mesh
          filename="package://robot_description/meshes/base_link.STL" />
      </geometry>
      <material
        name="">
        <color
          rgba="0.792156862745098 0.819607843137255 0.933333333333333 1" />
      </material>
    </visual>
    <collision>
      <origin
        xyz="0 0 0"
        rpy="0 0 0" />
      <geometry>
        <mesh
          filename="package://robot_description/meshes/base_link.STL" />
      </geometry>
    </collision>
  </link>
  <link
    name="left1_link">
    <inertial>
      <origin
        xyz="1.74895109449763E-06 0 0"
        rpy="0 0 0" />
      <mass
        value="0.18573457051178" />
      <inertia
        ixx="0.00014878560078214"
        ixy="2.61583694210615E-37"
        ixz="-5.55647484456475E-19"
        iyy="9.55881907150859E-05"
        iyz="7.85642079114842E-38"
        izz="9.55881907150859E-05" />
    </inertial>
    <visual>
      <origin
        xyz="0 0 0"
        rpy="0 0 0" />
      <geometry>
        <mesh
          filename="package://robot_description/meshes/left1_link.STL" />
      </geometry>
      <material
        name="">
        <color
          rgba="0.792156862745098 0.819607843137255 0.933333333333333 1" />
      </material>
    </visual>
    <collision>
      <origin
        xyz="0 0 0"
        rpy="0 0 0" />
      <geometry>
        <mesh
          filename="package://robot_description/meshes/left1_link.STL" />
      </geometry>
    </collision>
  </link>
  <joint
    name="left1_joint"
    type="continuous">
    <origin
      xyz="-0.109 0.11 -0.02"
      rpy="0 0 0" />
    <parent
      link="base_link" />
    <child
      link="left1_link" />
    <axis
      xyz="-1 0 0" />
  </joint>
  <link
    name="right1_link">
    <inertial>
      <origin
        xyz="-1.74895109450457E-06 0 0"
        rpy="0 0 0" />
      <mass
        value="0.18573457051178" />
      <inertia
        ixx="0.00014878560078214"
        ixy="5.31609239119842E-20"
        ixz="8.9290545596675E-21"
        iyy="9.55881907150857E-05"
        iyz="7.35634748938001E-21"
        izz="9.55881907150857E-05" />
    </inertial>
    <visual>
      <origin
        xyz="0 0 0"
        rpy="0 0 0" />
      <geometry>
        <mesh
          filename="package://robot_description/meshes/right1_link.STL" />
      </geometry>
      <material
        name="">
        <color
          rgba="0.792156862745098 0.819607843137255 0.933333333333333 1" />
      </material>
    </visual>
    <collision>
      <origin
        xyz="0 0 0"
        rpy="0 0 0" />
      <geometry>
        <mesh
          filename="package://robot_description/meshes/right1_link.STL" />
      </geometry>
    </collision>
  </link>
  <joint
    name="right1_joint"
    type="continuous">
    <origin
      xyz="0.109 0.11 -0.02"
      rpy="0 0 0" />
    <parent
      link="base_link" />
    <child
      link="right1_link" />
    <axis
      xyz="-1 0 0" />
  </joint>
  <link
    name="left2_link">
    <inertial>
      <origin
        xyz="1.74895109449069E-06 -1.38777878078145E-17 0"
        rpy="0 0 0" />
      <mass
        value="0.18573457051178" />
      <inertia
        ixx="0.00014878560078214"
        ixy="6.59077039371958E-20"
        ixz="-7.14722518869827E-21"
        iyy="9.55881907150859E-05"
        iyz="-7.25369432150928E-21"
        izz="9.55881907150859E-05" />
    </inertial>
    <visual>
      <origin
        xyz="0 0 0"
        rpy="0 0 0" />
      <geometry>
        <mesh
          filename="package://robot_description/meshes/left2_link.STL" />
      </geometry>
      <material
        name="">
        <color
          rgba="0.792156862745098 0.819607843137255 0.933333333333333 1" />
      </material>
    </visual>
    <collision>
      <origin
        xyz="0 0 0"
        rpy="0 0 0" />
      <geometry>
        <mesh
          filename="package://robot_description/meshes/left2_link.STL" />
      </geometry>
    </collision>
  </link>
  <joint
    name="left2_joint"
    type="continuous">
    <origin
      xyz="-0.109 -0.11 -0.02"
      rpy="0 0 0" />
    <parent
      link="base_link" />
    <child
      link="left2_link" />
    <axis
      xyz="1 0 0" />
  </joint>
  <link
    name="right2_link">
    <inertial>
      <origin
        xyz="-1.74895109450457E-06 1.38777878078145E-17 2.77555756156289E-17"
        rpy="0 0 0" />
      <mass
        value="0.18573457051178" />
      <inertia
        ixx="0.00014878560078214"
        ixy="6.69667896917803E-20"
        ixz="-7.18497798353105E-21"
        iyy="9.55881907150858E-05"
        iyz="4.06166316523365E-21"
        izz="9.55881907150858E-05" />
    </inertial>
    <visual>
      <origin
        xyz="0 0 0"
        rpy="0 0 0" />
      <geometry>
        <mesh
          filename="package://robot_description/meshes/right2_link.STL" />
      </geometry>
      <material
        name="">
        <color
          rgba="0.792156862745098 0.819607843137255 0.933333333333333 1" />
      </material>
    </visual>
    <collision>
      <origin
        xyz="0 0 0"
        rpy="0 0 0" />
      <geometry>
        <mesh
          filename="package://robot_description/meshes/right2_link.STL" />
      </geometry>
    </collision>
  </link>
  <joint
    name="right2_joint"
    type="continuous">
    <origin
      xyz="0.109 -0.11 -0.02"
      rpy="0 0 0" />
    <parent
      link="base_link" />
    <child
      link="right2_link" />
    <axis
      xyz="1 0 0" />
  </joint>
  <link
    name="laser_frame">
    <inertial>
      <origin
        xyz="4.07755298345858E-05 0.00829399933921326 -0.00854885777720904"
        rpy="0 0 0" />
      <mass
        value="0.146695752131392" />
      <inertia
        ixx="0.000109672851929357"
        ixy="-2.33034776451393E-07"
        ixz="9.27482598303586E-08"
        iyy="6.22732577408729E-05"
        iyz="1.88655796474337E-05"
        izz="0.000125682524275729" />
    </inertial>
    <visual>
      <origin
        xyz="0 0 0"
        rpy="0 0 0" />
      <geometry>
        <mesh
          filename="package://robot_description/meshes/lidar_link.STL" />
      </geometry>
      <material
        name="">
        <color
          rgba="0.792156862745098 0.819607843137255 0.933333333333333 1" />
      </material>
    </visual>
    <collision>
      <origin
        xyz="0 0 0"
        rpy="0 0 0" />
      <geometry>
        <mesh
          filename="package://robot_description/meshes/lidar_link.STL" />
      </geometry>
    </collision>
  </link>
  <joint
    name="laser_joint"
    type="fixed">
    <origin
      xyz="0.00077818 0.096194 0.14125"
      rpy="0 0 0" />
    <parent
      link="base_link" />
    <child
      link="laser_frame" />
    <axis
      xyz="0 0 0" />
  </joint>
</robot>